<?xml version="1.0" encoding="utf-8"?>
<!-- This URDF was automatically created by SolidWorks to URDF Exporter! Originally created by Stephen Brawner (brawner@gmail.com) 
     Commit Version: 1.6.0-4-g7f85cfe  Build Version: 1.6.7995.38578
     For more information, please see http://wiki.ros.org/sw_urdf_exporter -->
<robot name="robot" xmlns:xacro="http://www.ros.org/wiki/xacro">

  <xacro:include filename="$(find robot_description_r9)/urdf/robot_r9.gazebo"/> 
  
  <link name="base_footprint"/>

  <joint name="base_footprint_joint" type="fixed">
      <origin xyz="0 0 0.0" rpy="0 0 0" />
      <parent link="base_footprint"/>
      <child link="base_link"/>
  </joint>

  <link
  name="base_link">
  <inertial>
    <origin
      xyz="0.0423004561420601 -0.00159347451455082 0.117432623786484"
      rpy="0 0 0" />
    <mass
      value="18.6525196152106" />
    <inertia
      ixx="0.171005282140842"
      ixy="-2.96297236699276E-05"
      ixz="6.91823805775553E-05"
      iyy="0.152030402706163"
      iyz="8.60145591635783E-05"
      izz="0.25745541923206" />
  </inertial>
  <visual>
    <origin
      xyz="0 0 0"
      rpy="0 0 0" />
    <geometry>
      <mesh
        filename="package://robot_description_r9/meshes/base_link.STL" />
    </geometry>
    <material
      name="">
      <color
        rgba="0.686274509803922 0.607843137254902 0.529411764705882 1" />
    </material>
  </visual>
  <collision>
    <origin
      xyz="0 0 0"
      rpy="0 0 0" />
    <geometry>
      <mesh
        filename="package://robot_description_r9/meshes/base_link.STL" />
    </geometry>
  </collision>
</link>
<link
  name="Back_Right_Wheel_Link">
  <inertial>
    <origin
      xyz="5.0516E-06 0.033015 7.3553E-06"
      rpy="0 0 0" />
    <mass
      value="0.79712" />
    <inertia
      ixx="0.0016717"
      ixy="2.9311E-08"
      ixz="4.5368E-10"
      iyy="0.0030919"
      iyz="-1.9238E-07"
      izz="0.0016716" />
  </inertial>
  <visual>
    <origin
      xyz="0 0 0"
      rpy="0 0 0" />
    <geometry>
      <mesh
        filename="package://robot_description_r9/meshes/Link_BR.STL" />
    </geometry>
    <material
      name="">
      <color
        rgba="0.79216 0.81961 0.93333 1" />
    </material>
  </visual>
  <collision>
    <origin
      xyz="0 0 0"
      rpy="0 0 0" />
    <geometry>
      <mesh
        filename="package://robot_description_r9/meshes/Link_BR.STL" />
    </geometry>
  </collision>
</link>
<joint
  name="Back_Right_Wheel_Joint"
  type="continuous">
  <origin
    xyz="-0.165 -0.3307 0.0045"
    rpy="0 0 0" />
  <parent
    link="base_link" />
  <child
    link="Back_Right_Wheel_Link" />
  <axis
    xyz="0 1 0" />
</joint>
<link
  name="Back_Left_Wheel_Link">
  <inertial>
    <origin
      xyz="-5.0517E-06 -0.033015 7.3553E-06"
      rpy="0 0 0" />
    <mass
      value="0.79712" />
    <inertia
      ixx="0.0016717"
      ixy="2.9311E-08"
      ixz="-4.539E-10"
      iyy="0.0030919"
      iyz="1.9238E-07"
      izz="0.0016716" />
  </inertial>
  <visual>
    <origin
      xyz="0 0 0"
      rpy="0 0 0" />
    <geometry>
      <mesh
        filename="package://robot_description_r9/meshes/Link_BL.STL" />
    </geometry>
    <material
      name="">
      <color
        rgba="0.79216 0.81961 0.93333 1" />
    </material>
  </visual>
  <collision>
    <origin
      xyz="0 0 0"
      rpy="0 0 0" />
    <geometry>
      <mesh
        filename="package://robot_description_r9/meshes/Link_BL.STL" />
    </geometry>
  </collision>
</link>
<joint
  name="Back_Left_Wheel_Joint"
  type="continuous">
  <origin
    xyz="-0.165 0.3307 0.0045"
    rpy="0 0 0" />
  <parent
    link="base_link" />
  <child
    link="Back_Left_Wheel_Link" />
  <axis
    xyz="0 1 0" />
</joint>
<link
  name="Front_Right_Wheel_Link">
  <inertial>
    <origin
      xyz="5.0516E-06 0.033015 7.3553E-06"
      rpy="0 0 0" />
    <mass
      value="0.79712" />
    <inertia
      ixx="0.0016717"
      ixy="2.9311E-08"
      ixz="4.5377E-10"
      iyy="0.0030919"
      iyz="-1.9238E-07"
      izz="0.0016716" />
  </inertial>
  <visual>
    <origin
      xyz="0 0 0"
      rpy="0 0 0" />
    <geometry>
      <mesh
        filename="package://robot_description_r9/meshes/Link_FR.STL" />
    </geometry>
    <material
      name="">
      <color
        rgba="0.75294 0.75294 0.75294 1" />
    </material>
  </visual>
  <collision>
    <origin
      xyz="0 0 0"
      rpy="0 0 0" />
    <geometry>
      <mesh
        filename="package://robot_description_r9/meshes/Link_FR.STL" />
    </geometry>
  </collision>
</link>
<joint
  name="Front_Right_Wheel_Joint"
  type="continuous">
  <origin
    xyz="0.165 -0.3307 0.0045"
    rpy="0 0 0" />
  <parent
    link="base_link" />
  <child
    link="Front_Right_Wheel_Link" />
  <axis
    xyz="0 1 0" />
</joint>
<link
  name="Front_Left_Wheel_Link">
  <inertial>
    <origin
      xyz="-5.0516E-06 -0.033015 7.3553E-06"
      rpy="0 0 0" />
    <mass
      value="0.79712" />
    <inertia
      ixx="0.0016717"
      ixy="2.9311E-08"
      ixz="-4.5365E-10"
      iyy="0.0030919"
      iyz="1.9238E-07"
      izz="0.0016716" />
  </inertial>
  <visual>
    <origin
      xyz="0 0 0"
      rpy="0 0 0" />
    <geometry>
      <mesh
        filename="package://robot_description_r9/meshes/Link_FL.STL" />
    </geometry>
    <material
      name="">
      <color
        rgba="0.75294 0.75294 0.75294 1" />
    </material>
  </visual>
  <collision>
    <origin
      xyz="0 0 0"
      rpy="0 0 0" />
    <geometry>
      <mesh
        filename="package://robot_description_r9/meshes/Link_FL.STL" />
    </geometry>
  </collision>
</link>
<joint
  name="Front_Left_Wheel_Joint"
  type="continuous">
  <origin
    xyz="0.165 0.3307 0.0045"
    rpy="0 0 0" />
  <parent
    link="base_link" />
  <child
    link="Front_Left_Wheel_Link" />
  <axis
    xyz="0 1 0" />
</joint>
<link
  name="LiDAR_Link">
  <inertial>
    <origin
      xyz="0.0057758 0.00060438 -0.019562"
      rpy="0 0 0" />
    <mass
      value="0.14299" />
    <inertia
      ixx="4.6276E-05"
      ixy="-8.3569E-07"
      ixz="3.6217E-06"
      iyy="7.3476E-05"
      iyz="-2.0669E-07"
      izz="0.00010796" />
  </inertial>
  <visual>
    <origin
      xyz="0 0 0"
      rpy="0 0 0" />
    <geometry>
      <mesh
        filename="package://robot_description_r9/meshes/LiDAR_Link.STL" />
    </geometry>
    <material
      name="">
      <color
        rgba="0.79216 0.81961 0.93333 1" />
    </material>
  </visual>
  <collision>
    <origin
      xyz="0 0 0"
      rpy="0 0 0" />
    <geometry>
      <mesh
        filename="package://robot_description_r9/meshes/LiDAR_Link.STL" />
    </geometry>
  </collision>
</link>
<joint
  name="LiDAR_Joint"
  type="fixed">
  <origin
    xyz="-0.25369 -8.5025E-05 0.569"
    rpy="0 0 0" />
  <parent
    link="base_link" />
  <child
    link="LiDAR_Link" />
  <axis
    xyz="0 0 0" />
</joint>
<link
  name="IMU_Link">
  <inertial>
    <origin
      xyz="-0.00081359 5.5683E-05 -0.00080828"
      rpy="0 0 0" />
    <mass
      value="0.0010017" />
    <inertia
      ixx="3.0394E-08"
      ixy="1.306E-11"
      ixz="-6.2461E-14"
      iyy="1.6953E-08"
      iyz="3.3681E-18"
      izz="4.6329E-08" />
  </inertial>
  <visual>
    <origin
      xyz="0 0 0"
      rpy="0 0 0" />
    <geometry>
      <mesh
        filename="package://robot_description_r9/meshes/IMU_Link.STL" />
    </geometry>
    <material
      name="">
      <color
        rgba="0.75294 0.75294 0.75294 1" />
    </material>
  </visual>
  <collision>
    <origin
      xyz="0 0 0"
      rpy="0 0 0" />
    <geometry>
      <mesh
        filename="package://robot_description_r9/meshes/IMU_Link.STL" />
    </geometry>
  </collision>
</link>
<joint
  name="IMU_Joint"
  type="fixed">
  <origin
    xyz="0.037242 0 0.032143"
    rpy="0 0 -3.1416" />
  <parent
    link="base_link" />
  <child
    link="IMU_Link" />
  <axis
    xyz="0 0 0" />
</joint>
</robot>