<?xml version="1.0" encoding="utf-8"?>
<!-- This URDF was automatically created by SolidWorks to URDF Exporter! Originally created by Stephen Brawner (brawner@gmail.com) 
     Commit Version: 1.6.0-4-g7f85cfe  Build Version: 1.6.7995.38578
     For more information, please see http://wiki.ros.org/sw_urdf_exporter -->
<robot name="robot" xmlns:xacro="http://www.ros.org/wiki/xacro">

  <xacro:include filename="$(find robot_description_r9)/urdf/robot_r9.gazebo"/> 
  
  <link name="base_footprint"/>

  <joint name="base_footprint_joint" type="fixed">
      <origin xyz="0 0 0.0" rpy="0 0 0" />
      <parent link="base_footprint"/>
      <child link="base_link"/>
  </joint>

  <link
  name="base_link">
  <inertial>
    <origin
      xyz="-0.0409735201954065 0.00157229402165202 0.119483535274084"
      rpy="0 0 0" />
    <mass
      value="18.7595571477401" />
    <inertia
      ixx="0.170418512070609"
      ixy="-3.05696326503954E-05"
      ixz="3.242888282834E-05"
      iyy="0.151470059770373"
      iyz="-8.62075122637916E-05"
      izz="0.257547775912216" />
  </inertial>
  <visual>
    <origin
      xyz="0 0 0"
      rpy="0 0 0" />
    <geometry>
      <mesh
        filename="package://robot_description_r9/meshes/base_link.STL" />
    </geometry>
    <material
      name="">
      <color
        rgba="0.792156862745098 0.819607843137255 0.933333333333333 1" />
    </material>
  </visual>
  <collision>
    <origin
      xyz="0 0 0"
      rpy="0 0 0" />
    <geometry>
      <mesh
        filename="package://robot_description_r9/meshes/base_link.STL" />
    </geometry>
  </collision>
</link>
<link
  name="Front_Left_Wheel_Link">
  <inertial>
    <origin
      xyz="-5.0514E-06 -0.033015 7.3553E-06"
      rpy="0 0 0" />
    <mass
      value="0.79712" />
    <inertia
      ixx="0.0016717"
      ixy="2.9311E-08"
      ixz="-4.5313E-10"
      iyy="0.0030919"
      iyz="1.9238E-07"
      izz="0.0016716" />
  </inertial>
  <visual>
    <origin
      xyz="0 0 0"
      rpy="0 0 0" />
    <geometry>
      <mesh
        filename="package://robot_description_r9/meshes/Link_FL.STL" />
    </geometry>
    <material
      name="">
      <color
        rgba="0.75294 0.75294 0.75294 1" />
    </material>
  </visual>
  <collision>
    <origin
      xyz="0 0 0"
      rpy="0 0 0" />
    <geometry>
      <mesh
        filename="package://robot_description_r9/meshes/Link_FL.STL" />
    </geometry>
  </collision>
</link>
<joint
  name="Front_Left_Wheel_Joint"
  type="continuous">
  <origin
    xyz="0.165 0.3307 0.0045"
    rpy="0 0 0" />
  <parent
    link="base_link" />
  <child
    link="Front_Left_Wheel_Link" />
  <axis
    xyz="0 1 0" />
</joint>
<link
  name="Front_Right_Wheel_Link">
  <inertial>
    <origin
      xyz="5.0517E-06 0.033015 7.3553E-06"
      rpy="0 0 0" />
    <mass
      value="0.79712" />
    <inertia
      ixx="0.0016717"
      ixy="2.9311E-08"
      ixz="4.5388E-10"
      iyy="0.0030919"
      iyz="-1.9238E-07"
      izz="0.0016716" />
  </inertial>
  <visual>
    <origin
      xyz="0 0 0"
      rpy="0 0 0" />
    <geometry>
      <mesh
        filename="package://robot_description_r9/meshes/Link_FR.STL" />
    </geometry>
    <material
      name="">
      <color
        rgba="0.75294 0.75294 0.75294 1" />
    </material>
  </visual>
  <collision>
    <origin
      xyz="0 0 0"
      rpy="0 0 0" />
    <geometry>
      <mesh
        filename="package://robot_description_r9/meshes/Link_FR.STL" />
    </geometry>
  </collision>
</link>
<joint
  name="Front_Right_Wheel_Joint"
  type="continuous">
  <origin
    xyz="0.165 -0.3307 0.0045"
    rpy="0 0 0" />
  <parent
    link="base_link" />
  <child
    link="Front_Right_Wheel_Link" />
  <axis
    xyz="0 1 0" />
</joint>
<link
  name="Back_Left_Wheel_Link">
  <inertial>
    <origin
      xyz="-5.0516E-06 -0.033015 7.3553E-06"
      rpy="0 0 0" />
    <mass
      value="0.79712" />
    <inertia
      ixx="0.0016717"
      ixy="2.9311E-08"
      ixz="-4.5377E-10"
      iyy="0.0030919"
      iyz="1.9238E-07"
      izz="0.0016716" />
  </inertial>
  <visual>
    <origin
      xyz="0 0 0"
      rpy="0 0 0" />
    <geometry>
      <mesh
        filename="package://robot_description_r9/meshes/Link_BL.STL" />
    </geometry>
    <material
      name="">
      <color
        rgba="0.75294 0.75294 0.75294 1" />
    </material>
  </visual>
  <collision>
    <origin
      xyz="0 0 0"
      rpy="0 0 0" />
    <geometry>
      <mesh
        filename="package://robot_description_r9/meshes/Link_BL.STL" />
    </geometry>
  </collision>
</link>
<joint
  name="Back_Left_Wheel_Joint"
  type="continuous">
  <origin
    xyz="-0.165 0.3307 0.0045"
    rpy="0 0 0" />
  <parent
    link="base_link" />
  <child
    link="Back_Left_Wheel_Link" />
  <axis
    xyz="0 1 0" />
</joint>
<link
  name="Back_Right_Wheel_Link">
  <inertial>
    <origin
      xyz="5.0516E-06 0.033015 7.3553E-06"
      rpy="0 0 0" />
    <mass
      value="0.79712" />
    <inertia
      ixx="0.0016717"
      ixy="2.9311E-08"
      ixz="4.5365E-10"
      iyy="0.0030919"
      iyz="-1.9238E-07"
      izz="0.0016716" />
  </inertial>
  <visual>
    <origin
      xyz="0 0 0"
      rpy="0 0 0" />
    <geometry>
      <mesh
        filename="package://robot_description_r9/meshes/Link_BR.STL" />
    </geometry>
    <material
      name="">
      <color
        rgba="0.75294 0.75294 0.75294 1" />
    </material>
  </visual>
  <collision>
    <origin
      xyz="0 0 0"
      rpy="0 0 0" />
    <geometry>
      <mesh
        filename="package://robot_description_r9/meshes/Link_BR.STL" />
    </geometry>
  </collision>
</link>
<joint
  name="Back_Right_Wheel_Joint"
  type="continuous">
  <origin
    xyz="-0.165 -0.3307 0.0045"
    rpy="0 0 0" />
  <parent
    link="base_link" />
  <child
    link="Back_Right_Wheel_Link" />
  <axis
    xyz="0 1 0" />
</joint>

<link
name="LiDAR_Link">
<inertial>
  <origin
    xyz="0.0057735 0.00062673 -0.019562"
    rpy="0 0 0" />
  <mass
    value="0.14299" />
  <inertia
    ixx="4.6282E-05"
    ixy="-9.4095E-07"
    ixz="3.6225E-06"
    iyy="7.3469E-05"
    iyz="-1.9267E-07"
    izz="0.00010796" />
</inertial>
<visual>
  <origin
    xyz="0 0 0"
    rpy="0 0 0" />
  <geometry>
    <mesh
      filename="package://robot_description_r9/meshes/LiDAR_Link.STL" />
  </geometry>
  <material
    name="">
    <color
      rgba="0.79216 0.81961 0.93333 1" />
  </material>
</visual>
<collision>
  <origin
    xyz="0 0 0"
    rpy="0 0 0" />
  <geometry>
    <mesh
      filename="package://robot_description_r9/meshes/LiDAR_Link.STL" />
  </geometry>
</collision>
</link>
<joint
name="LiDAR_Joint"
type="fixed">
<origin
  xyz="0.21631 -0.00025017 0.519"
  rpy="0 0 0" />
<parent
  link="base_link" />
<child
  link="LiDAR_Link" />
<axis
  xyz="0 0 1" />
</joint>
</robot>